Workbook

Sheet 設定
A1: Aether 見積・実行予算システム（試作版）
A2: 作成日 | B2: 46165
A3: 消費税率 | B3: 0.1 | C3: お客様見積書の税込計算に使用
A4: 目標粗利率 | B4: 0.3 | C4: 社内実行予算書の判定に使用
A5: 最低粗利率（警告） | B5: 0.25 | C5: 下回ると警告表示
A6: 会社名 | B6: 株式会社Aether
A7: 代表者 | B7: 伊藤 雄一
A8: 備考 | B8: 入力シートへ一度入力すると、お客様見積書・社内実行予算書へ反映されます。
A9: 見積有効期限（日数） | B9: 30 | C9: 作成日からの有効日数
A10: お支払条件 | B10: 着手金50％、完工時残金50％ | C10: お客様見積書に表示
A11: 振込先 | B11: （銀行名・支店名・口座番号を記入） | C11: お客様見積書に表示
A12: 特記事項 | B12: 別途、現場状況により追加費用が発生する場合があります。 | C12: お客様見積書に表示

Sheet 入力シート
A1: No | B1: 部屋・工区 | C1: カテゴリ | D1: 工事項目 | E1: 数量 | F1: 単位 | G1: お客様単価 | H1: お客様手入力金額 | I1: お客様金額 | J1: 実行数量 | K1: 実行単位 | L1: 実行単価 | M1: 実行手入力金額 | N1: 実行金額 | O1: 粗利額 | P1: 粗利率 | Q1: 定価・掛率・人工費 | R1: 商品名・品番・メーカー | S1: 表示 | T1: 備考
A2: 1 | B2: 玄関ホール、廊下、階段室吹抜 | C2: 材料 | D2: 床 上り框 | E2: 1 | F2: 本 | G2: 8600 | I2: =IF($A2="","",IF($S2<>"表示",0,IF($H2>0,$H2,IFERROR($E2*$G2,0)))) | J2: 1 | K2: 本 | L2: 5320 | N2: =IF($A2="","",IF($S2<>"表示",0,IF($M2>0,$M2,IFERROR($J2*$L2,0)))) | O2: =IF($A2="","",$I2-$N2) | P2: =IF($A2="","",IFERROR($O2/$I2,0)) | Q2: 定価15,200円/本（2,000㎜）×35％ | R2: ノダ リフォーム上り框 7㎜厚 | S2: 表示
A3: 2 | B3: 玄関ホール、廊下、階段室吹抜 | C3: 材料 | D3: 床 フローリング | E3: 2 | F3: 梱 | G3: 8000 | I3: =IF($A3="","",IF($S3<>"表示",0,IF($H3>0,$H3,IFERROR($E3*$G3,0)))) | J3: 2 | K3: 梱 | L3: 4550 | N3: =IF($A3="","",IF($S3<>"表示",0,IF($M3>0,$M3,IFERROR($J3*$L3,0)))) | O3: =IF($A3="","",$I3-$N3) | P3: =IF($A3="","",IFERROR($O3/$I3,0)) | Q3: 定価13,000円/梱（3.3㎡）×35％ | R3: ノダ ウォークフィット6 6.3㎜厚 | S3: 表示
A4: 3 | B4: 玄関ホール、廊下、階段室吹抜 | C4: 材料 | D4: 巾木 | E4: 2 | F4: 本 | G4: 900 | I4: =IF($A4="","",IF($S4<>"表示",0,IF($H4>0,$H4,IFERROR($E4*$G4,0)))) | J4: 2 | K4: 本 | L4: 735 | N4: =IF($A4="","",IF($S4<>"表示",0,IF($M4>0,$M4,IFERROR($J4*$L4,0)))) | O4: =IF($A4="","",$I4-$N4) | P4: =IF($A4="","",IFERROR($O4/$I4,0)) | Q4: 定価2,100円/本×35％ | R4: ノダ 巾木C 7×60×3,950㎜（3本入） | S4: 表示
A5: 4 | B5: 玄関ホール、廊下、階段室吹抜 | C5: 材料 | D5: リフォーム階段（直14段）踏板 | E5: 13 | F5: 枚 | G5: 1400 | I5: =IF($A5="","",IF($S5<>"表示",0,IF($H5>0,$H5,IFERROR($E5*$G5,0)))) | J5: 13 | K5: 枚 | L5: 1330 | N5: =IF($A5="","",IF($S5<>"表示",0,IF($M5>0,$M5,IFERROR($J5*$L5,0)))) | O5: =IF($A5="","",$I5-$N5) | P5: =IF($A5="","",IFERROR($O5/$I5,0)) | Q5: 定価3,800円×35％ | R5: ノダ リフォーム階段 | S5: 表示
A6: 5 | B6: 玄関ホール、廊下、階段室吹抜 | C6: 材料 | D6: 〃 蹴込板 | E6: 14 | F6: 枚 | G6: 900 | I6: =IF($A6="","",IF($S6<>"表示",0,IF($H6>0,$H6,IFERROR($E6*$G6,0)))) | J6: 14 | K6: 枚 | L6: 315 | N6: =IF($A6="","",IF($S6<>"表示",0,IF($M6>0,$M6,IFERROR($J6*$L6,0)))) | O6: =IF($A6="","",$I6-$N6) | P6: =IF($A6="","",IFERROR($O6/$I6,0)) | Q6: 定価900円×35％ | R6: 〃 〃 | S6: 表示
A7: 6 | B7: 玄関ホール、廊下、階段室吹抜 | C7: 材料 | D7: 〃 段鼻部材 | E7: 13 | F7: 本 | G7: 2700 | I7: =IF($A7="","",IF($S7<>"表示",0,IF($H7>0,$H7,IFERROR($E7*$G7,0)))) | J7: 13 | K7: 本 | L7: 630 | N7: =IF($A7="","",IF($S7<>"表示",0,IF($M7>0,$M7,IFERROR($J7*$L7,0)))) | O7: =IF($A7="","",$I7-$N7) | P7: =IF($A7="","",IFERROR($O7/$I7,0)) | Q7: 定価1,800円×35％ | R7: 〃 〃 | S7: 表示
A8: 7 | B8: 玄関ホール、廊下、階段室吹抜 | C8: 材料 | D8: 〃 上段框用段鼻部材 | E8: 1 | F8: 本 | G8: 3000 | I8: =IF($A8="","",IF($S8<>"表示",0,IF($H8>0,$H8,IFERROR($E8*$G8,0)))) | J8: 1 | K8: 本 | L8: 630 | N8: =IF($A8="","",IF($S8<>"表示",0,IF($M8>0,$M8,IFERROR($J8*$L8,0)))) | O8: =IF($A8="","",$I8-$N8) | P8: =IF($A8="","",IFERROR($O8/$I8,0)) | Q8: 定価1,800円×35％ | R8: 〃 〃 | S8: 表示
A9: 8 | B9: 玄関ホール、廊下、階段室吹抜 | C9: 材料 | D9: 玄関収納 W120×H226cm 床置 | E9: 1 | F9: セット | G9: 66100 | I9: =IF($A9="","",IF($S9<>"表示",0,IF($H9>0,$H9,IFERROR($E9*$G9,0)))) | J9: 1 | K9: セット | L9: 53165 | N9: =IF($A9="","",IF($S9<>"表示",0,IF($M9>0,$M9,IFERROR($J9*$L9,0)))) | O9: =IF($A9="","",$I9-$N9) | P9: =IF($A9="","",IFERROR($O9/$I9,0)) | Q9: 定価151,900円×35％ | R9: ノダ 玄関収納コの字フラット | S9: 表示
A10: 9 | B10: 玄関ホール、廊下、階段室吹抜 | C10: 材料 | D10: 取替用玄関ドア（片袖） | E10: 1 | F10: セット | G10: 165700 | I10: =IF($A10="","",IF($S10<>"表示",0,IF($H10>0,$H10,IFERROR($E10*$G10,0)))) | J10: 1 | K10: セット | L10: 114100 | N10: =IF($A10="","",IF($S10<>"表示",0,IF($M10>0,$M10,IFERROR($J10*$L10,0)))) | O10: =IF($A10="","",$I10-$N10) | P10: =IF($A10="","",IFERROR($O10/$I10,0)) | Q10: 定価326,000円×35％ | R10: LIXIL リシェント アルミ仕様 | S10: 表示
A11: 10 | B11: 玄関ホール、廊下、階段室吹抜 | C11: 材料 | D11: 袖部ランマ袖部ガラス | E11: 1 | F11: 式 | H11: 6200 | I11: =IF($A11="","",IF($S11<>"表示",0,IF($H11>0,$H11,IFERROR($E11*$G11,0)))) | J11: 1 | K11: 式 | M11: 4650 | N11: =IF($A11="","",IF($S11<>"表示",0,IF($M11>0,$M11,IFERROR($J11*$L11,0)))) | O11: =IF($A11="","",$I11-$N11) | P11: =IF($A11="","",IFERROR($O11/$I11,0)) | R11: 5㎜ガラス | S11: 表示
A12: 11 | B12: 玄関ホール、廊下、階段室吹抜 | C12: 材料 | D12: 木枠塗装剤 | E12: 1 | F12: 式 | H12: 3200 | I12: =IF($A12="","",IF($S12<>"表示",0,IF($H12>0,$H12,IFERROR($E12*$G12,0)))) | J12: 1 | K12: 式 | M12: 2400 | N12: =IF($A12="","",IF($S12<>"表示",0,IF($M12>0,$M12,IFERROR($J12*$L12,0)))) | O12: =IF($A12="","",$I12-$N12) | P12: =IF($A12="","",IFERROR($O12/$I12,0)) | S12: 表示
A13: 12 | B13: 玄関ホール、廊下、階段室吹抜 | C13: 施工 | D13: 床 上り框取付 | E13: 1 | F13: 式 | H13: 4200 | I13: =IF($A13="","",IF($S13<>"表示",0,IF($H13>0,$H13,IFERROR($E13*$G13,0)))) | J13: 1 | K13: 式 | M13: 3000 | N13: =IF($A13="","",IF($S13<>"表示",0,IF($M13>0,$M13,IFERROR($J13*$L13,0)))) | O13: =IF($A13="","",$I13-$N13) | P13: =IF($A13="","",IFERROR($O13/$I13,0)) | S13: 表示
A14: 13 | B14: 玄関ホール、廊下、階段室吹抜 | C14: 施工 | D14: 床 フローリング重ね貼り | E14: 5.2 | F14: ㎡ | G14: 2140 | I14: =IF($A14="","",IF($S14<>"表示",0,IF($H14>0,$H14,IFERROR($E14*$G14,0)))) | J14: 5.2 | K14: ㎡ | L14: 1500 | N14: =IF($A14="","",IF($S14<>"表示",0,IF($M14>0,$M14,IFERROR($J14*$L14,0)))) | O14: =IF($A14="","",$I14-$N14) | P14: =IF($A14="","",IFERROR($O14/$I14,0)) | S14: 表示
A15: 14 | B15: 玄関ホール、廊下、階段室吹抜 | C15: 施工 | D15: 巾木取替え | E15: 6.4 | F15: ｍ | G15: 1140 | I15: =IF($A15="","",IF($S15<>"表示",0,IF($H15>0,$H15,IFERROR($E15*$G15,0)))) | J15: 6.4 | K15: m | L15: 800 | N15: =IF($A15="","",IF($S15<>"表示",0,IF($M15>0,$M15,IFERROR($J15*$L15,0)))) | O15: =IF($A15="","",$I15-$N15) | P15: =IF($A15="","",IFERROR($O15/$I15,0)) | S15: 表示
A16: 15 | B16: 玄関ホール、廊下、階段室吹抜 | C16: 施工 | D16: リフォーム階段（直14段）重ね貼り | E16: 1 | F16: 式 | H16: 28500 | I16: =IF($A16="","",IF($S16<>"表示",0,IF($H16>0,$H16,IFERROR($E16*$G16,0)))) | J16: 1 | K16: 式 | M16: 20000 | N16: =IF($A16="","",IF($S16<>"表示",0,IF($M16>0,$M16,IFERROR($J16*$L16,0)))) | O16: =IF($A16="","",$I16-$N16) | P16: =IF($A16="","",IFERROR($O16/$I16,0)) | Q16: 1人役 | S16: 表示
A17: 16 | B17: 玄関ホール、廊下、階段室吹抜 | C17: 施工 | D17: 既存玄関ドア撤去 | E17: 1 | F17: 式 | H17: 7100 | I17: =IF($A17="","",IF($S17<>"表示",0,IF($H17>0,$H17,IFERROR($E17*$G17,0)))) | J17: 1 | K17: 式 | M17: 5000 | N17: =IF($A17="","",IF($S17<>"表示",0,IF($M17>0,$M17,IFERROR($J17*$L17,0)))) | O17: =IF($A17="","",$I17-$N17) | P17: =IF($A17="","",IFERROR($O17/$I17,0)) | S17: 表示
A18: 17 | B18: 玄関ホール、廊下、階段室吹抜 | C18: 施工 | D18: 玄関ドア（リフォームドア）取替え | E18: 1 | F18: 式 | H18: 28500 | I18: =IF($A18="","",IF($S18<>"表示",0,IF($H18>0,$H18,IFERROR($E18*$G18,0)))) | J18: 1 | K18: 式 | M18: 20000 | N18: =IF($A18="","",IF($S18<>"表示",0,IF($M18>0,$M18,IFERROR($J18*$L18,0)))) | O18: =IF($A18="","",$I18-$N18) | P18: =IF($A18="","",IFERROR($O18/$I18,0)) | Q18: 1人役 | S18: 表示
A19: 18 | B19: 玄関ホール、廊下、階段室吹抜 | C19: 施工 | D19: 玄関収納取替え | E19: 1 | F19: 式 | H19: 11400 | I19: =IF($A19="","",IF($S19<>"表示",0,IF($H19>0,$H19,IFERROR($E19*$G19,0)))) | J19: 1 | K19: 式 | M19: 8000 | N19: =IF($A19="","",IF($S19<>"表示",0,IF($M19>0,$M19,IFERROR($J19*$L19,0)))) | O19: =IF($A19="","",$I19-$N19) | P19: =IF($A19="","",IFERROR($O19/$I19,0)) | Q19: 1/3人役 | S19: 表示
A20: 19 | B20: 玄関ホール、廊下、階段室吹抜 | C20: 施工 | D20: 天井 ビニールクロス貼替え | E20: 7.3 | F20: ㎡ | G20: 1140 | I20: =IF($A20="","",IF($S20<>"表示",0,IF($H20>0,$H20,IFERROR($E20*$G20,0)))) | J20: 7.3 | K20: ㎡ | L20: 650 | N20: =IF($A20="","",IF($S20<>"表示",0,IF($M20>0,$M20,IFERROR($J20*$L20,0)))) | O20: =IF($A20="","",$I20-$N20) | P20: =IF($A20="","",IFERROR($O20/$I20,0)) | Q20: 材工共 | R20: 量産品 SP | S20: 表示
A21: 20 | B21: 玄関ホール、廊下、階段室吹抜 | C21: 施工 | D21: 壁 〃 | E21: 50 | F21: ㎡ | G21: 1140 | I21: =IF($A21="","",IF($S21<>"表示",0,IF($H21>0,$H21,IFERROR($E21*$G21,0)))) | J21: 50 | K21: ㎡ | L21: 650 | N21: =IF($A21="","",IF($S21<>"表示",0,IF($M21>0,$M21,IFERROR($J21*$L21,0)))) | O21: =IF($A21="","",$I21-$N21) | P21: =IF($A21="","",IFERROR($O21/$I21,0)) | Q21: 材工共 | R21: 量産品 SP | S21: 表示
A22: 21 | B22: 玄関ホール、廊下、階段室吹抜 | C22: 施工 | D22: 木枠塗装 | E22: 1 | F22: 式 | H22: 11400 | I22: =IF($A22="","",IF($S22<>"表示",0,IF($H22>0,$H22,IFERROR($E22*$G22,0)))) | J22: 1 | K22: 式 | M22: 8000 | N22: =IF($A22="","",IF($S22<>"表示",0,IF($M22>0,$M22,IFERROR($J22*$L22,0)))) | O22: =IF($A22="","",$I22-$N22) | P22: =IF($A22="","",IFERROR($O22/$I22,0)) | Q22: 1/3人役 | S22: 表示
A23: 22 | B23: 玄関ホール、廊下、階段室吹抜 | C23: 施工 | D23: プレート取替え | E23: 3 | F23: セット | G23: 850 | I23: =IF($A23="","",IF($S23<>"表示",0,IF($H23>0,$H23,IFERROR($E23*$G23,0)))) | J23: 3 | K23: セット | L23: 600 | N23: =IF($A23="","",IF($S23<>"表示",0,IF($M23>0,$M23,IFERROR($J23*$L23,0)))) | O23: =IF($A23="","",$I23-$N23) | P23: =IF($A23="","",IFERROR($O23/$I23,0)) | Q23: 材工共 | S23: 表示
A24: 23 | B24: LDK | C24: 材料 | D24: 床 フローリング | E24: 7 | F24: 梱 | G24: 8000 | I24: =IF($A24="","",IF($S24<>"表示",0,IF($H24>0,$H24,IFERROR($E24*$G24,0)))) | J24: 7 | K24: 梱 | L24: 4550 | N24: =IF($A24="","",IF($S24<>"表示",0,IF($M24>0,$M24,IFERROR($J24*$L24,0)))) | O24: =IF($A24="","",$I24-$N24) | P24: =IF($A24="","",IFERROR($O24/$I24,0)) | Q24: 定価13,000円/梱（3.3㎡）×35％ | R24: ノダ ウォークフィット6 6.3㎜厚 | S24: 表示
A25: 24 | B25: LDK | C25: 材料 | D25: 巾木 | E25: 4 | F25: 本 | G25: 900 | I25: =IF($A25="","",IF($S25<>"表示",0,IF($H25>0,$H25,IFERROR($E25*$G25,0)))) | J25: 4 | K25: 本 | L25: 735 | N25: =IF($A25="","",IF($S25<>"表示",0,IF($M25>0,$M25,IFERROR($J25*$L25,0)))) | O25: =IF($A25="","",$I25-$N25) | P25: =IF($A25="","",IFERROR($O25/$I25,0)) | Q25: 定価2,100円/本×35％ | R25: ノダ 巾木C 7×60×3,950㎜（3本入） ☆ | S25: 表示
A26: 25 | B26: LDK | C26: 材料 | D26: リビング片開き戸（ドアのみガラス入） | E26: 1 | F26: セット | G26: 57300 | I26: =IF($A26="","",IF($S26<>"表示",0,IF($H26>0,$H26,IFERROR($E26*$G26,0)))) | J26: 1 | K26: セット | L26: 43000 | N26: =IF($A26="","",IF($S26<>"表示",0,IF($M26>0,$M26,IFERROR($J26*$L26,0)))) | O26: =IF($A26="","",$I26-$N26) | P26: =IF($A26="","",IFERROR($O26/$I26,0)) | R26: 別注 フラッシュ框ドア（ガラス入）金物含む | S26: 表示
A27: 26 | B27: LDK | C27: 材料 | D27: 〃 （ドアのみ） | E27: 1 | F27: セット | G27: 24000 | I27: =IF($A27="","",IF($S27<>"表示",0,IF($H27>0,$H27,IFERROR($E27*$G27,0)))) | J27: 1 | K27: セット | L27: 18000 | N27: =IF($A27="","",IF($S27<>"表示",0,IF($M27>0,$M27,IFERROR($J27*$L27,0)))) | O27: =IF($A27="","",$I27-$N27) | P27: =IF($A27="","",IFERROR($O27/$I27,0)) | R27: 別注 プリント貼り フラッシュドア 金物含む | S27: 表示
A28: 27 | B28: LDK | C28: 材料 | D28: システムキッチン I型2550 | E28: 1 | F28: セット | G28: 261600 | I28: =IF($A28="","",IF($S28<>"表示",0,IF($H28>0,$H28,IFERROR($E28*$G28,0)))) | J28: 1 | K28: セット | L28: 196230 | N28: =IF($A28="","",IF($S28<>"表示",0,IF($M28>0,$M28,IFERROR($J28*$L28,0)))) | O28: =IF($A28="","",$I28-$N28) | P28: =IF($A28="","",IFERROR($O28/$I28,0)) | Q28: 定価633,000円×31％ | R28: トクラス Bb スライドタイプ 扉E/C ☆ | S28: 表示
A29: 28 | B29: LDK | C29: 材料 | D29: キッチンパネル | E29: 2 | F29: 枚 | G29: 12600 | I29: =IF($A29="","",IF($S29<>"表示",0,IF($H29>0,$H29,IFERROR($E29*$G29,0)))) | J29: 2 | K29: 枚 | L29: 9464 | N29: =IF($A29="","",IF($S29<>"表示",0,IF($M29>0,$M29,IFERROR($J29*$L29,0)))) | O29: =IF($A29="","",$I29-$N29) | P29: =IF($A29="","",IFERROR($O29/$I29,0)) | Q29: 定価18,200円/枚×52％マ | R29: アイカ工業 セラール 3×8 ☆ | S29: 表示
A30: 29 | B30: LDK | C30: 材料 | D30: 〃 施工部材 | E30: 1 | F30: セット | G30: 6500 | I30: =IF($A30="","",IF($S30<>"表示",0,IF($H30>0,$H30,IFERROR($E30*$G30,0)))) | J30: 1 | K30: セット | L30: 4929 | N30: =IF($A30="","",IF($S30<>"表示",0,IF($M30>0,$M30,IFERROR($J30*$L30,0)))) | O30: =IF($A30="","",$I30-$N30) | P30: =IF($A30="","",IFERROR($O30/$I30,0)) | Q30: 定価9,300円×53％ | R30: 専用接着剤 見切りジョイナー（2本） ☆ | S30: 表示
A31: 30 | B31: LDK | C31: 材料 | D31: 〃 下地材 | E31: 1 | F31: 式 | H31: 13300 | I31: =IF($A31="","",IF($S31<>"表示",0,IF($H31>0,$H31,IFERROR($E31*$G31,0)))) | J31: 1 | K31: 式 | M31: 10000 | N31: =IF($A31="","",IF($S31<>"表示",0,IF($M31>0,$M31,IFERROR($J31*$L31,0)))) | O31: =IF($A31="","",$I31-$N31) | P31: =IF($A31="","",IFERROR($O31/$I31,0)) | R31: 合板及び銅縁材他 | S31: 表示
A32: 31 | B32: LDK | C32: 材料 | D32: 木枠塗装剤ウ | E32: 1 | F32: 式 | H32: 10600 | I32: =IF($A32="","",IF($S32<>"表示",0,IF($H32>0,$H32,IFERROR($E32*$G32,0)))) | J32: 1 | K32: 式 | M32: 8000 | N32: =IF($A32="","",IF($S32<>"表示",0,IF($M32>0,$M32,IFERROR($J32*$L32,0)))) | O32: =IF($A32="","",$I32-$N32) | P32: =IF($A32="","",IFERROR($O32/$I32,0)) | S32: 表示
A33: 32 | B33: LDK | C33: 施工 | D33: 床 フローリング重ね貼り | E33: 23.2 | F33: ㎡ | G33: 2140 | I33: =IF($A33="","",IF($S33<>"表示",0,IF($H33>0,$H33,IFERROR($E33*$G33,0)))) | J33: 23.2 | K33: ㎡ | L33: 1500 | N33: =IF($A33="","",IF($S33<>"表示",0,IF($M33>0,$M33,IFERROR($J33*$L33,0)))) | O33: =IF($A33="","",$I33-$N33) | P33: =IF($A33="","",IFERROR($O33/$I33,0)) | S33: 表示
A34: 33 | B34: LDK | C34: 施工 | D34: 巾木取替え | E34: 14.8 | F34: m | G34: 850 | I34: =IF($A34="","",IF($S34<>"表示",0,IF($H34>0,$H34,IFERROR($E34*$G34,0)))) | J34: 14.8 | K34: m | L34: 600 | N34: =IF($A34="","",IF($S34<>"表示",0,IF($M34>0,$M34,IFERROR($J34*$L34,0)))) | O34: =IF($A34="","",$I34-$N34) | P34: =IF($A34="","",IFERROR($O34/$I34,0)) | S34: 表示
A35: 34 | B35: LDK | C35: 施工 | D35: 片開き戸取替え 2ヶ所 | E35: 1 | F35: 式 | H35: 8400 | I35: =IF($A35="","",IF($S35<>"表示",0,IF($H35>0,$H35,IFERROR($E35*$G35,0)))) | J35: 1 | K35: 式 | M35: 6000 | N35: =IF($A35="","",IF($S35<>"表示",0,IF($M35>0,$M35,IFERROR($J35*$L35,0)))) | O35: =IF($A35="","",$I35-$N35) | P35: =IF($A35="","",IFERROR($O35/$I35,0)) | R35: 建付調整 | S35: 表示
A36: 35 | B36: LDK | C36: 施工 | D36: 解体工事（既存キッチン） | E36: 1 | F36: 式 | H36: 28500 | I36: =IF($A36="","",IF($S36<>"表示",0,IF($H36>0,$H36,IFERROR($E36*$G36,0)))) | J36: 1 | K36: 式 | M36: 20000 | N36: =IF($A36="","",IF($S36<>"表示",0,IF($M36>0,$M36,IFERROR($J36*$L36,0)))) | O36: =IF($A36="","",$I36-$N36) | P36: =IF($A36="","",IFERROR($O36/$I36,0)) | Q36: 1人役 | S36: 表示
A37: 36 | B37: LDK | C37: 経費 | D37: 〃 廃棄費 | E37: 1 | F37: 式 | H37: 21400 | I37: =IF($A37="","",IF($S37<>"表示",0,IF($H37>0,$H37,IFERROR($E37*$G37,0)))) | J37: 1 | K37: 式 | M37: 15000 | N37: =IF($A37="","",IF($S37<>"表示",0,IF($M37>0,$M37,IFERROR($J37*$L37,0)))) | O37: =IF($A37="","",$I37-$N37) | P37: =IF($A37="","",IFERROR($O37/$I37,0)) | S37: 表示
A38: 37 | B38: LDK | C38: 施工 | D38: システムキッチン取付 | E38: 1 | F38: 式 | H38: 57100 | I38: =IF($A38="","",IF($S38<>"表示",0,IF($H38>0,$H38,IFERROR($E38*$G38,0)))) | J38: 1 | K38: 式 | M38: 40000 | N38: =IF($A38="","",IF($S38<>"表示",0,IF($M38>0,$M38,IFERROR($J38*$L38,0)))) | O38: =IF($A38="","",$I38-$N38) | P38: =IF($A38="","",IFERROR($O38/$I38,0)) | Q38: 1人役 | S38: 表示
A39: 38 | B39: LDK | C39: 施工 | D39: キッチンパネル下地工事 | E39: 1 | F39: 式 | H39: 28500 | I39: =IF($A39="","",IF($S39<>"表示",0,IF($H39>0,$H39,IFERROR($E39*$G39,0)))) | J39: 1 | K39: 式 | M39: 20000 | N39: =IF($A39="","",IF($S39<>"表示",0,IF($M39>0,$M39,IFERROR($J39*$L39,0)))) | O39: =IF($A39="","",$I39-$N39) | P39: =IF($A39="","",IFERROR($O39/$I39,0)) | Q39: 1/3人役 | S39: 表示
A40: 39 | B40: LDK | C40: 施工 | D40: 〃 取付 | E40: 1 | F40: 式 | H40: 28500 | I40: =IF($A40="","",IF($S40<>"表示",0,IF($H40>0,$H40,IFERROR($E40*$G40,0)))) | J40: 1 | K40: 式 | M40: 20000 | N40: =IF($A40="","",IF($S40<>"表示",0,IF($M40>0,$M40,IFERROR($J40*$L40,0)))) | O40: =IF($A40="","",$I40-$N40) | P40: =IF($A40="","",IFERROR($O40/$I40,0)) | S40: 表示
...

Sheet お客様見積書
A1: 御見積書
D3: 様 | F3: 作成日 | G3: ='設定'!$B$2
A4: 工事名 | B4: リフォーム工事一式 | F4: 会社名 | G4: ='設定'!$B$6
F5: 代表 | G5: ='設定'!$B$7
A7: 工区・部屋 | B7: 小計（税抜） | C7: 消費税 | D7: 税込金額 | E7: 備考
A8: 玄関ホール、廊下、階段室吹抜 | B8: =SUMIFS('入力シート'!$I$2:$I$301,'入力シート'!$B$2:$B$301,$A8,'入力シート'!$S$2:$S$301,"表示") | C8: =ROUNDDOWN(B8*'設定'!$B$3,0) | D8: =B8+C8
A9: LDK | B9: =SUMIFS('入力シート'!$I$2:$I$301,'入力シート'!$B$2:$B$301,$A9,'入力シート'!$S$2:$S$301,"表示") | C9: =ROUNDDOWN(B9*'設定'!$B$3,0) | D9: =B9+C9
A10: 浴室 | B10: =SUMIFS('入力シート'!$I$2:$I$301,'入力シート'!$B$2:$B$301,$A10,'入力シート'!$S$2:$S$301,"表示") | C10: =ROUNDDOWN(B10*'設定'!$B$3,0) | D10: =B10+C10
A11: 洗面所 | B11: =SUMIFS('入力シート'!$I$2:$I$301,'入力シート'!$B$2:$B$301,$A11,'入力シート'!$S$2:$S$301,"表示") | C11: =ROUNDDOWN(B11*'設定'!$B$3,0) | D11: =B11+C11
A12: トイレ | B12: =SUMIFS('入力シート'!$I$2:$I$301,'入力シート'!$B$2:$B$301,$A12,'入力シート'!$S$2:$S$301,"表示") | C12: =ROUNDDOWN(B12*'設定'!$B$3,0) | D12: =B12+C12
A13: 1F 和室6帖 | B13: =SUMIFS('入力シート'!$I$2:$I$301,'入力シート'!$B$2:$B$301,$A13,'入力シート'!$S$2:$S$301,"表示") | C13: =ROUNDDOWN(B13*'設定'!$B$3,0) | D13: =B13+C13
A14: 2F 和室 4.5帖 | B14: =SUMIFS('入力シート'!$I$2:$I$301,'入力シート'!$B$2:$B$301,$A14,'入力シート'!$S$2:$S$301,"表示") | C14: =ROUNDDOWN(B14*'設定'!$B$3,0) | D14: =B14+C14
A15: 2F 洋間8帖 A | B15: =SUMIFS('入力シート'!$I$2:$I$301,'入力シート'!$B$2:$B$301,$A15,'入力シート'!$S$2:$S$301,"表示") | C15: =ROUNDDOWN(B15*'設定'!$B$3,0) | D15: =B15+C15
A16: 2F 洋間6帖 B | B16: =SUMIFS('入力シート'!$I$2:$I$301,'入力シート'!$B$2:$B$301,$A16,'入力シート'!$S$2:$S$301,"表示") | C16: =ROUNDDOWN(B16*'設定'!$B$3,0) | D16: =B16+C16
A17: 2F 廊下 | B17: =SUMIFS('入力シート'!$I$2:$I$301,'入力シート'!$B$2:$B$301,$A17,'入力シート'!$S$2:$S$301,"表示") | C17: =ROUNDDOWN(B17*'設定'!$B$3,0) | D17: =B17+C17
A18: 屋根 | B18: =SUMIFS('入力シート'!$I$2:$I$301,'入力シート'!$B$2:$B$301,$A18,'入力シート'!$S$2:$S$301,"表示") | C18: =ROUNDDOWN(B18*'設定'!$B$3,0) | D18: =B18+C18
A19: 外壁 | B19: =SUMIFS('入力シート'!$I$2:$I$301,'入力シート'!$B$2:$B$301,$A19,'入力シート'!$S$2:$S$301,"表示") | C19: =ROUNDDOWN(B19*'設定'!$B$3,0) | D19: =B19+C19
A20: 未分類（下記一覧にない工区） | B20: =SUMIFS('入力シート'!$I$2:$I$301,'入力シート'!$S$2:$S$301,"表示")-SUM(B8:B19) | C20: =ROUNDDOWN(B20*'設定'!$B$3,0) | D20: =B20+C20
A21: 値引き（税抜・マイナスで入力） | B21: 0 | C21: =-ROUNDDOWN(-B21*'設定'!$B$3,0) | D21: =B21+C21
A22: 合計 | B22: =SUM(B8:B21) | C22: =SUM(C8:C21) | D22: =SUM(D8:D21)
A24: お支払条件 | B24: ='設定'!$B$10
A25: 見積有効期限 | B25: ='設定'!$B$2+'設定'!$B$9
A26: 振込先 | B26: ='設定'!$B$11
A27: 特記事項 | B27: ='設定'!$B$12

Sheet お客様見積書_詳細
A1: No | B1: 部屋・工区 | C1: 工事項目 | D1: 数量 | E1: 単位 | F1: 単価 | G1: 金額 | H1: 備考
A2: =IFERROR(IF('入力シート'!$S2="表示",'入力シート'!A2,""),"") | B2: =IFERROR(IF('入力シート'!$S2="表示",'入力シート'!B2,""),"") | C2: =IFERROR(IF('入力シート'!$S2="表示",'入力シート'!D2,""),"") | D2: =IFERROR(IF('入力シート'!$S2="表示",'入力シート'!E2,""),"") | E2: =IFERROR(IF('入力シート'!$S2="表示",'入力シート'!F2,""),"") | F2: =IFERROR(IF('入力シート'!$S2="表示",'入力シート'!G2,""),"") | G2: =IFERROR(IF('入力シート'!$S2="表示",'入力シート'!I2,""),"") | H2: =IFERROR(IF('入力シート'!$S2="表示",'入力シート'!R2,""),"")
A3: =IFERROR(IF('入力シート'!$S3="表示",'入力シート'!A3,""),"") | B3: =IFERROR(IF('入力シート'!$S3="表示",'入力シート'!B3,""),"") | C3: =IFERROR(IF('入力シート'!$S3="表示",'入力シート'!D3,""),"") | D3: =IFERROR(IF('入力シート'!$S3="表示",'入力シート'!E3,""),"") | E3: =IFERROR(IF('入力シート'!$S3="表示",'入力シート'!F3,""),"") | F3: =IFERROR(IF('入力シート'!$S3="表示",'入力シート'!G3,""),"") | G3: =IFERROR(IF('入力シート'!$S3="表示",'入力シート'!I3,""),"") | H3: =IFERROR(IF('入力シート'!$S3="表示",'入力シート'!R3,""),"")
A4: =IFERROR(IF('入力シート'!$S4="表示",'入力シート'!A4,""),"") | B4: =IFERROR(IF('入力シート'!$S4="表示",'入力シート'!B4,""),"") | C4: =IFERROR(IF('入力シート'!$S4="表示",'入力シート'!D4,""),"") | D4: =IFERROR(IF('入力シート'!$S4="表示",'入力シート'!E4,""),"") | E4: =IFERROR(IF('入力シート'!$S4="表示",'入力シート'!F4,""),"") | F4: =IFERROR(IF('入力シート'!$S4="表示",'入力シート'!G4,""),"") | G4: =IFERROR(IF('入力シート'!$S4="表示",'入力シート'!I4,""),"") | H4: =IFERROR(IF('入力シート'!$S4="表示",'入力シート'!R4,""),"")
A5: =IFERROR(IF('入力シート'!$S5="表示",'入力シート'!A5,""),"") | B5: =IFERROR(IF('入力シート'!$S5="表示",'入力シート'!B5,""),"") | C5: =IFERROR(IF('入力シート'!$S5="表示",'入力シート'!D5,""),"") | D5: =IFERROR(IF('入力シート'!$S5="表示",'入力シート'!E5,""),"") | E5: =IFERROR(IF('入力シート'!$S5="表示",'入力シート'!F5,""),"") | F5: =IFERROR(IF('入力シート'!$S5="表示",'入力シート'!G5,""),"") | G5: =IFERROR(IF('入力シート'!$S5="表示",'入力シート'!I5,""),"") | H5: =IFERROR(IF('入力シート'!$S5="表示",'入力シート'!R5,""),"")
A6: =IFERROR(IF('入力シート'!$S6="表示",'入力シート'!A6,""),"") | B6: =IFERROR(IF('入力シート'!$S6="表示",'入力シート'!B6,""),"") | C6: =IFERROR(IF('入力シート'!$S6="表示",'入力シート'!D6,""),"") | D6: =IFERROR(IF('入力シート'!$S6="表示",'入力シート'!E6,""),"") | E6: =IFERROR(IF('入力シート'!$S6="表示",'入力シート'!F6,""),"") | F6: =IFERROR(IF('入力シート'!$S6="表示",'入力シート'!G6,""),"") | G6: =IFERROR(IF('入力シート'!$S6="表示",'入力シート'!I6,""),"") | H6: =IFERROR(IF('入力シート'!$S6="表示",'入力シート'!R6,""),"")
A7: =IFERROR(IF('入力シート'!$S7="表示",'入力シート'!A7,""),"") | B7: =IFERROR(IF('入力シート'!$S7="表示",'入力シート'!B7,""),"") | C7: =IFERROR(IF('入力シート'!$S7="表示",'入力シート'!D7,""),"") | D7: =IFERROR(IF('入力シート'!$S7="表示",'入力シート'!E7,""),"") | E7: =IFERROR(IF('入力シート'!$S7="表示",'入力シート'!F7,""),"") | F7: =IFERROR(IF('入力シート'!$S7="表示",'入力シート'!G7,""),"") | G7: =IFERROR(IF('入力シート'!$S7="表示",'入力シート'!I7,""),"") | H7: =IFERROR(IF('入力シート'!$S7="表示",'入力シート'!R7,""),"")
A8: =IFERROR(IF('入力シート'!$S8="表示",'入力シート'!A8,""),"") | B8: =IFERROR(IF('入力シート'!$S8="表示",'入力シート'!B8,""),"") | C8: =IFERROR(IF('入力シート'!$S8="表示",'入力シート'!D8,""),"") | D8: =IFERROR(IF('入力シート'!$S8="表示",'入力シート'!E8,""),"") | E8: =IFERROR(IF('入力シート'!$S8="表示",'入力シート'!F8,""),"") | F8: =IFERROR(IF('入力シート'!$S8="表示",'入力シート'!G8,""),"") | G8: =IFERROR(IF('入力シート'!$S8="表示",'入力シート'!I8,""),"") | H8: =IFERROR(IF('入力シート'!$S8="表示",'入力シート'!R8,""),"")
A9: =IFERROR(IF('入力シート'!$S9="表示",'入力シート'!A9,""),"") | B9: =IFERROR(IF('入力シート'!$S9="表示",'入力シート'!B9,""),"") | C9: =IFERROR(IF('入力シート'!$S9="表示",'入力シート'!D9,""),"") | D9: =IFERROR(IF('入力シート'!$S9="表示",'入力シート'!E9,""),"") | E9: =IFERROR(IF('入力シート'!$S9="表示",'入力シート'!F9,""),"") | F9: =IFERROR(IF('入力シート'!$S9="表示",'入力シート'!G9,""),"") | G9: =IFERROR(IF('入力シート'!$S9="表示",'入力シート'!I9,""),"") | H9: =IFERROR(IF('入力シート'!$S9="表示",'入力シート'!R9,""),"")
A10: =IFERROR(IF('入力シート'!$S10="表示",'入力シート'!A10,""),"") | B10: =IFERROR(IF('入力シート'!$S10="表示",'入力シート'!B10,""),"") | C10: =IFERROR(IF('入力シート'!$S10="表示",'入力シート'!D10,""),"") | D10: =IFERROR(IF('入力シート'!$S10="表示",'入力シート'!E10,""),"") | E10: =IFERROR(IF('入力シート'!$S10="表示",'入力シート'!F10,""),"") | F10: =IFERROR(IF('入力シート'!$S10="表示",'入力シート'!G10,""),"") | G10: =IFERROR(IF('入力シート'!$S10="表示",'入力シート'!I10,""),"") | H10: =IFERROR(IF('入力シート'!$S10="表示",'入力シート'!R10,""),"")
A11: =IFERROR(IF('入力シート'!$S11="表示",'入力シート'!A11,""),"") | B11: =IFERROR(IF('入力シート'!$S11="表示",'入力シート'!B11,""),"") | C11: =IFERROR(IF('入力シート'!$S11="表示",'入力シート'!D11,""),"") | D11: =IFERROR(IF('入力シート'!$S11="表示",'入力シート'!E11,""),"") | E11: =IFERROR(IF('入力シート'!$S11="表示",'入力シート'!F11,""),"") | F11: =IFERROR(IF('入力シート'!$S11="表示",'入力シート'!G11,""),"") | G11: =IFERROR(IF('入力シート'!$S11="表示",'入力シート'!I11,""),"") | H11: =IFERROR(IF('入力シート'!$S11="表示",'入力シート'!R11,""),"")
A12: =IFERROR(IF('入力シート'!$S12="表示",'入力シート'!A12,""),"") | B12: =IFERROR(IF('入力シート'!$S12="表示",'入力シート'!B12,""),"") | C12: =IFERROR(IF('入力シート'!$S12="表示",'入力シート'!D12,""),"") | D12: =IFERROR(IF('入力シート'!$S12="表示",'入力シート'!E12,""),"") | E12: =IFERROR(IF('入力シート'!$S12="表示",'入力シート'!F12,""),"") | F12: =IFERROR(IF('入力シート'!$S12="表示",'入力シート'!G12,""),"") | G12: =IFERROR(IF('入力シート'!$S12="表示",'入力シート'!I12,""),"") | H12: =IFERROR(IF('入力シート'!$S12="表示",'入力シート'!R12,""),"")
A13: =IFERROR(IF('入力シート'!$S13="表示",'入力シート'!A13,""),"") | B13: =IFERROR(IF('入力シート'!$S13="表示",'入力シート'!B13,""),"") | C13: =IFERROR(IF('入力シート'!$S13="表示",'入力シート'!D13,""),"") | D13: =IFERROR(IF('入力シート'!$S13="表示",'入力シート'!E13,""),"") | E13: =IFERROR(IF('入力シート'!$S13="表示",'入力シート'!F13,""),"") | F13: =IFERROR(IF('入力シート'!$S13="表示",'入力シート'!G13,""),"") | G13: =IFERROR(IF('入力シート'!$S13="表示",'入力シート'!I13,""),"") | H13: =IFERROR(IF('入力シート'!$S13="表示",'入力シート'!R13,""),"")
... A301: =IFERROR(IF('入力シート'!$S301="表示",'入力シート'!A301,""),"") | B301: =IFERROR(IF('入力シート'!$S301="表示",'入力シート'!B301,""),"") | C301: =IFERROR(IF('入力シート'!$S301="表示",'入力シート'!D301,""),"") | D301: =IFERROR(IF('入力シート'!$S301="表示",'入力シート'!E301,""),"") | E301: =IFERROR(IF('入力シート'!$S301="表示",'入力シート'!F301,""),"") | F301: =IFERROR(IF('入力シート'!$S301="表示",'入力シート'!G301,""),"") | G301: =IFERROR(IF('入力シート'!$S301="表示",'入力シート'!I301,""),"") | H301: =IFERROR(IF('入力シート'!$S301="表示",'入力シート'!R301,""),"")

Sheet 社内実行予算書
A1: 社内実行予算書
A3: 工区・部屋 | B3: お客様見積 | C3: 社内実行予算 | D3: 粗利額 | E3: 粗利率 | F3: 目標粗利率 | G3: 判定 | H3: 備考
A4: 玄関ホール、廊下、階段室吹抜 | B4: =SUMIFS('入力シート'!$I$2:$I$301,'入力シート'!$B$2:$B$301,$A4,'入力シート'!$S$2:$S$301,"表示") | C4: =SUMIFS('入力シート'!$N$2:$N$301,'入力シート'!$B$2:$B$301,$A4,'入力シート'!$S$2:$S$301,"表示") | D4: =B4-C4 | E4: =IFERROR(D4/B4,0) | F4: ='設定'!$B$4 | G4: =IF(E4>='設定'!$B$4,"OK",IF(E4>='設定'!$B$5,"注意","要改善"))
A5: LDK | B5: =SUMIFS('入力シート'!$I$2:$I$301,'入力シート'!$B$2:$B$301,$A5,'入力シート'!$S$2:$S$301,"表示") | C5: =SUMIFS('入力シート'!$N$2:$N$301,'入力シート'!$B$2:$B$301,$A5,'入力シート'!$S$2:$S$301,"表示") | D5: =B5-C5 | E5: =IFERROR(D5/B5,0) | F5: ='設定'!$B$4 | G5: =IF(E5>='設定'!$B$4,"OK",IF(E5>='設定'!$B$5,"注意","要改善"))
A6: 浴室 | B6: =SUMIFS('入力シート'!$I$2:$I$301,'入力シート'!$B$2:$B$301,$A6,'入力シート'!$S$2:$S$301,"表示") | C6: =SUMIFS('入力シート'!$N$2:$N$301,'入力シート'!$B$2:$B$301,$A6,'入力シート'!$S$2:$S$301,"表示") | D6: =B6-C6 | E6: =IFERROR(D6/B6,0) | F6: ='設定'!$B$4 | G6: =IF(E6>='設定'!$B$4,"OK",IF(E6>='設定'!$B$5,"注意","要改善"))
A7: 洗面所 | B7: =SUMIFS('入力シート'!$I$2:$I$301,'入力シート'!$B$2:$B$301,$A7,'入力シート'!$S$2:$S$301,"表示") | C7: =SUMIFS('入力シート'!$N$2:$N$301,'入力シート'!$B$2:$B$301,$A7,'入力シート'!$S$2:$S$301,"表示") | D7: =B7-C7 | E7: =IFERROR(D7/B7,0) | F7: ='設定'!$B$4 | G7: =IF(E7>='設定'!$B$4,"OK",IF(E7>='設定'!$B$5,"注意","要改善"))
A8: トイレ | B8: =SUMIFS('入力シート'!$I$2:$I$301,'入力シート'!$B$2:$B$301,$A8,'入力シート'!$S$2:$S$301,"表示") | C8: =SUMIFS('入力シート'!$N$2:$N$301,'入力シート'!$B$2:$B$301,$A8,'入力シート'!$S$2:$S$301,"表示") | D8: =B8-C8 | E8: =IFERROR(D8/B8,0) | F8: ='設定'!$B$4 | G8: =IF(E8>='設定'!$B$4,"OK",IF(E8>='設定'!$B$5,"注意","要改善"))
A9: 1F 和室6帖 | B9: =SUMIFS('入力シート'!$I$2:$I$301,'入力シート'!$B$2:$B$301,$A9,'入力シート'!$S$2:$S$301,"表示") | C9: =SUMIFS('入力シート'!$N$2:$N$301,'入力シート'!$B$2:$B$301,$A9,'入力シート'!$S$2:$S$301,"表示") | D9: =B9-C9 | E9: =IFERROR(D9/B9,0) | F9: ='設定'!$B$4 | G9: =IF(E9>='設定'!$B$4,"OK",IF(E9>='設定'!$B$5,"注意","要改善"))
A10: 2F 和室 4.5帖 | B10: =SUMIFS('入力シート'!$I$2:$I$301,'入力シート'!$B$2:$B$301,$A10,'入力シート'!$S$2:$S$301,"表示") | C10: =SUMIFS('入力シート'!$N$2:$N$301,'入力シート'!$B$2:$B$301,$A10,'入力シート'!$S$2:$S$301,"表示") | D10: =B10-C10 | E10: =IFERROR(D10/B10,0) | F10: ='設定'!$B$4 | G10: =IF(E10>='設定'!$B$4,"OK",IF(E10>='設定'!$B$5,"注意","要改善"))
A11: 2F 洋間8帖 A | B11: =SUMIFS('入力シート'!$I$2:$I$301,'入力シート'!$B$2:$B$301,$A11,'入力シート'!$S$2:$S$301,"表示") | C11: =SUMIFS('入力シート'!$N$2:$N$301,'入力シート'!$B$2:$B$301,$A11,'入力シート'!$S$2:$S$301,"表示") | D11: =B11-C11 | E11: =IFERROR(D11/B11,0) | F11: ='設定'!$B$4 | G11: =IF(E11>='設定'!$B$4,"OK",IF(E11>='設定'!$B$5,"注意","要改善"))
A12: 2F 洋間6帖 B | B12: =SUMIFS('入力シート'!$I$2:$I$301,'入力シート'!$B$2:$B$301,$A12,'入力シート'!$S$2:$S$301,"表示") | C12: =SUMIFS('入力シート'!$N$2:$N$301,'入力シート'!$B$2:$B$301,$A12,'入力シート'!$S$2:$S$301,"表示") | D12: =B12-C12 | E12: =IFERROR(D12/B12,0) | F12: ='設定'!$B$4 | G12: =IF(E12>='設定'!$B$4,"OK",IF(E12>='設定'!$B$5,"注意","要改善"))
A13: 2F 廊下 | B13: =SUMIFS('入力シート'!$I$2:$I$301,'入力シート'!$B$2:$B$301,$A13,'入力シート'!$S$2:$S$301,"表示") | C13: =SUMIFS('入力シート'!$N$2:$N$301,'入力シート'!$B$2:$B$301,$A13,'入力シート'!$S$2:$S$301,"表示") | D13: =B13-C13 | E13: =IFERROR(D13/B13,0) | F13: ='設定'!$B$4 | G13: =IF(E13>='設定'!$B$4,"OK",IF(E13>='設定'!$B$5,"注意","要改善"))
A14: 屋根 | B14: =SUMIFS('入力シート'!$I$2:$I$301,'入力シート'!$B$2:$B$301,$A14,'入力シート'!$S$2:$S$301,"表示") | C14: =SUMIFS('入力シート'!$N$2:$N$301,'入力シート'!$B$2:$B$301,$A14,'入力シート'!$S$2:$S$301,"表示") | D14: =B14-C14 | E14: =IFERROR(D14/B14,0) | F14: ='設定'!$B$4 | G14: =IF(E14>='設定'!$B$4,"OK",IF(E14>='設定'!$B$5,"注意","要改善"))
A15: 外壁 | B15: =SUMIFS('入力シート'!$I$2:$I$301,'入力シート'!$B$2:$B$301,$A15,'入力シート'!$S$2:$S$301,"表示") | C15: =SUMIFS('入力シート'!$N$2:$N$301,'入力シート'!$B$2:$B$301,$A15,'入力シート'!$S$2:$S$301,"表示") | D15: =B15-C15 | E15: =IFERROR(D15/B15,0) | F15: ='設定'!$B$4 | G15: =IF(E15>='設定'!$B$4,"OK",IF(E15>='設定'!$B$5,"注意","要改善"))
A16: 未分類（下記一覧にない工区） | B16: =SUMIFS('入力シート'!$I$2:$I$301,'入力シート'!$S$2:$S$301,"表示")-SUM(B4:B15) | C16: =SUMIFS('入力シート'!$N$2:$N$301,'入力シート'!$S$2:$S$301,"表示")-SUM(C4:C15) | D16: =B16-C16 | E16: =IFERROR(D16/B16,0) | F16: ='設定'!$B$4 | G16: =IF(B16=0,"",IF(E16>='設定'!$B$4,"OK",IF(E16>='設定'!$B$5,"注意","要改善")))
A17: 値引き（税抜） | B17: ='お客様見積書'!B21 | C17: 0 | D17: =B17-C17
A18: 合計（値引後） | B18: =SUM(B4:B17) | C18: =SUM(C4:C17) | D18: =B18-C18 | E18: =IFERROR(D18/B18,0) | F18: ='設定'!$B$4 | G18: =IF(E18>='設定'!$B$4,"OK",IF(E18>='設定'!$B$5,"注意","要改善"))

Sheet 社内実行予算書_明細
A1: No | B1: 部屋・工区 | C1: カテゴリ | D1: 工事項目 | E1: お客様金額 | F1: 実行金額 | G1: 粗利額 | H1: 粗利率 | I1: 定価・掛率・人工費 | J1: 商品名・メーカー | K1: 判定
A2: =IFERROR(IF('入力シート'!$A2="","",'入力シート'!A2),"") | B2: =IFERROR(IF('入力シート'!$A2="","",'入力シート'!B2),"") | C2: =IFERROR(IF('入力シート'!$A2="","",'入力シート'!C2),"") | D2: =IFERROR(IF('入力シート'!$A2="","",'入力シート'!D2),"") | E2: =IFERROR(IF('入力シート'!$A2="","",'入力シート'!I2),"") | F2: =IFERROR(IF('入力シート'!$A2="","",'入力シート'!N2),"") | G2: =IFERROR(IF('入力シート'!$A2="","",'入力シート'!O2),"") | H2: =IFERROR(IF('入力シート'!$A2="","",'入力シート'!P2),"") | I2: =IFERROR(IF('入力シート'!$A2="","",'入力シート'!Q2),"") | J2: =IFERROR(IF('入力シート'!$A2="","",'入力シート'!R2),"") | K2: =IFERROR(IF('入力シート'!$A2="","",IF(H2>='設定'!$B$4,"OK",IF(H2>='設定'!$B$5,"注意","要改善"))),"")
A3: =IFERROR(IF('入力シート'!$A3="","",'入力シート'!A3),"") | B3: =IFERROR(IF('入力シート'!$A3="","",'入力シート'!B3),"") | C3: =IFERROR(IF('入力シート'!$A3="","",'入力シート'!C3),"") | D3: =IFERROR(IF('入力シート'!$A3="","",'入力シート'!D3),"") | E3: =IFERROR(IF('入力シート'!$A3="","",'入力シート'!I3),"") | F3: =IFERROR(IF('入力シート'!$A3="","",'入力シート'!N3),"") | G3: =IFERROR(IF('入力シート'!$A3="","",'入力シート'!O3),"") | H3: =IFERROR(IF('入力シート'!$A3="","",'入力シート'!P3),"") | I3: =IFERROR(IF('入力シート'!$A3="","",'入力シート'!Q3),"") | J3: =IFERROR(IF('入力シート'!$A3="","",'入力シート'!R3),"") | K3: =IFERROR(IF('入力シート'!$A3="","",IF(H3>='設定'!$B$4,"OK",IF(H3>='設定'!$B$5,"注意","要改善"))),"")
A4: =IFERROR(IF('入力シート'!$A4="","",'入力シート'!A4),"") | B4: =IFERROR(IF('入力シート'!$A4="","",'入力シート'!B4),"") | C4: =IFERROR(IF('入力シート'!$A4="","",'入力シート'!C4),"") | D4: =IFERROR(IF('入力シート'!$A4="","",'入力シート'!D4),"") | E4: =IFERROR(IF('入力シート'!$A4="","",'入力シート'!I4),"") | F4: =IFERROR(IF('入力シート'!$A4="","",'入力シート'!N4),"") | G4: =IFERROR(IF('入力シート'!$A4="","",'入力シート'!O4),"") | H4: =IFERROR(IF('入力シート'!$A4="","",'入力シート'!P4),"") | I4: =IFERROR(IF('入力シート'!$A4="","",'入力シート'!Q4),"") | J4: =IFERROR(IF('入力シート'!$A4="","",'入力シート'!R4),"") | K4: =IFERROR(IF('入力シート'!$A4="","",IF(H4>='設定'!$B$4,"OK",IF(H4>='設定'!$B$5,"注意","要改善"))),"")
A5: =IFERROR(IF('入力シート'!$A5="","",'入力シート'!A5),"") | B5: =IFERROR(IF('入力シート'!$A5="","",'入力シート'!B5),"") | C5: =IFERROR(IF('入力シート'!$A5="","",'入力シート'!C5),"") | D5: =IFERROR(IF('入力シート'!$A5="","",'入力シート'!D5),"") | E5: =IFERROR(IF('入力シート'!$A5="","",'入力シート'!I5),"") | F5: =IFERROR(IF('入力シート'!$A5="","",'入力シート'!N5),"") | G5: =IFERROR(IF('入力シート'!$A5="","",'入力シート'!O5),"") | H5: =IFERROR(IF('入力シート'!$A5="","",'入力シート'!P5),"") | I5: =IFERROR(IF('入力シート'!$A5="","",'入力シート'!Q5),"") | J5: =IFERROR(IF('入力シート'!$A5="","",'入力シート'!R5),"") | K5: =IFERROR(IF('入力シート'!$A5="","",IF(H5>='設定'!$B$4,"OK",IF(H5>='設定'!$B$5,"注意","要改善"))),"")
A6: =IFERROR(IF('入力シート'!$A6="","",'入力シート'!A6),"") | B6: =IFERROR(IF('入力シート'!$A6="","",'入力シート'!B6),"") | C6: =IFERROR(IF('入力シート'!$A6="","",'入力シート'!C6),"") | D6: =IFERROR(IF('入力シート'!$A6="","",'入力シート'!D6),"") | E6: =IFERROR(IF('入力シート'!$A6="","",'入力シート'!I6),"") | F6: =IFERROR(IF('入力シート'!$A6="","",'入力シート'!N6),"") | G6: =IFERROR(IF('入力シート'!$A6="","",'入力シート'!O6),"") | H6: =IFERROR(IF('入力シート'!$A6="","",'入力シート'!P6),"") | I6: =IFERROR(IF('入力シート'!$A6="","",'入力シート'!Q6),"") | J6: =IFERROR(IF('入力シート'!$A6="","",'入力シート'!R6),"") | K6: =IFERROR(IF('入力シート'!$A6="","",IF(H6>='設定'!$B$4,"OK",IF(H6>='設定'!$B$5,"注意","要改善"))),"")
A7: =IFERROR(IF('入力シート'!$A7="","",'入力シート'!A7),"") | B7: =IFERROR(IF('入力シート'!$A7="","",'入力シート'!B7),"") | C7: =IFERROR(IF('入力シート'!$A7="","",'入力シート'!C7),"") | D7: =IFERROR(IF('入力シート'!$A7="","",'入力シート'!D7),"") | E7: =IFERROR(IF('入力シート'!$A7="","",'入力シート'!I7),"") | F7: =IFERROR(IF('入力シート'!$A7="","",'入力シート'!N7),"") | G7: =IFERROR(IF('入力シート'!$A7="","",'入力シート'!O7),"") | H7: =IFERROR(IF('入力シート'!$A7="","",'入力シート'!P7),"") | I7: =IFERROR(IF('入力シート'!$A7="","",'入力シート'!Q7),"") | J7: =IFERROR(IF('入力シート'!$A7="","",'入力シート'!R7),"") | K7: =IFERROR(IF('入力シート'!$A7="","",IF(H7>='設定'!$B$4,"OK",IF(H7>='設定'!$B$5,"注意","要改善"))),"")
A8: =IFERROR(IF('入力シート'!$A8="","",'入力シート'!A8),"") | B8: =IFERROR(IF('入力シート'!$A8="","",'入力シート'!B8),"") | C8: =IFERROR(IF('入力シート'!$A8="","",'入力シート'!C8),"") | D8: =IFERROR(IF('入力シート'!$A8="","",'入力シート'!D8),"") | E8: =IFERROR(IF('入力シート'!$A8="","",'入力シート'!I8),"") | F8: =IFERROR(IF('入力シート'!$A8="","",'入力シート'!N8),"") | G8: =IFERROR(IF('入力シート'!$A8="","",'入力シート'!O8),"") | H8: =IFERROR(IF('入力シート'!$A8="","",'入力シート'!P8),"") | I8: =IFERROR(IF('入力シート'!$A8="","",'入力シート'!Q8),"") | J8: =IFERROR(IF('入力シート'!$A8="","",'入力シート'!R8),"") | K8: =IFERROR(IF('入力シート'!$A8="","",IF(H8>='設定'!$B$4,"OK",IF(H8>='設定'!$B$5,"注意","要改善"))),"")
A9: =IFERROR(IF('入力シート'!$A9="","",'入力シート'!A9),"") | B9: =IFERROR(IF('入力シート'!$A9="","",'入力シート'!B9),"") | C9: =IFERROR(IF('入力シート'!$A9="","",'入力シート'!C9),"") | D9: =IFERROR(IF('入力シート'!$A9="","",'入力シート'!D9),"") | E9: =IFERROR(IF('入力シート'!$A9="","",'入力シート'!I9),"") | F9: =IFERROR(IF('入力シート'!$A9="","",'入力シート'!N9),"") | G9: =IFERROR(IF('入力シート'!$A9="","",'入力シート'!O9),"") | H9: =IFERROR(IF('入力シート'!$A9="","",'入力シート'!P9),"") | I9: =IFERROR(IF('入力シート'!$A9="","",'入力シート'!Q9),"") | J9: =IFERROR(IF('入力シート'!$A9="","",'入力シート'!R9),"") | K9: =IFERROR(IF('入力シート'!$A9="","",IF(H9>='設定'!$B$4,"OK",IF(H9>='設定'!$B$5,"注意","要改善"))),"")
A10: =IFERROR(IF('入力シート'!$A10="","",'入力シート'!A10),"") | B10: =IFERROR(IF('入力シート'!$A10="","",'入力シート'!B10),"") | C10: =IFERROR(IF('入力シート'!$A10="","",'入力シート'!C10),"") | D10: =IFERROR(IF('入力シート'!$A10="","",'入力シート'!D10),"") | E10: =IFERROR(IF('入力シート'!$A10="","",'入力シート'!I10),"") | F10: =IFERROR(IF('入力シート'!$A10="","",'入力シート'!N10),"") | G10: =IFERROR(IF('入力シート'!$A10="","",'入力シート'!O10),"") | H10: =IFERROR(IF('入力シート'!$A10="","",'入力シート'!P10),"") | I10: =IFERROR(IF('入力シート'!$A10="","",'入力シート'!Q10),"") | J10: =IFERROR(IF('入力シート'!$A10="","",'入力シート'!R10),"") | K10: =IFERROR(IF('入力シート'!$A10="","",IF(H10>='設定'!$B$4,"OK",IF(H10>='設定'!$B$5,"注意","要改善"))),"")
A11: =IFERROR(IF('入力シート'!$A11="","",'入力シート'!A11),"") | B11: =IFERROR(IF('入力シート'!$A11="","",'入力シート'!B11),"") | C11: =IFERROR(IF('入力シート'!$A11="","",'入力シート'!C11),"") | D11: =IFERROR(IF('入力シート'!$A11="","",'入力シート'!D11),"") | E11: =IFERROR(IF('入力シート'!$A11="","",'入力シート'!I11),"") | F11: =IFERROR(IF('入力シート'!$A11="","",'入力シート'!N11),"") | G11: =IFERROR(IF('入力シート'!$A11="","",'入力シート'!O11),"") | H11: =IFERROR(IF('入力シート'!$A11="","",'入力シート'!P11),"") | I11: =IFERROR(IF('入力シート'!$A11="","",'入力シート'!Q11),"") | J11: =IFERROR(IF('入力シート'!$A11="","",'入力シート'!R11),"") | K11: =IFERROR(IF('入力シート'!$A11="","",IF(H11>='設定'!$B$4,"OK",IF(H11>='設定'!$B$5,"注意","要改善"))),"")
A12: =IFERROR(IF('入力シート'!$A12="","",'入力シート'!A12),"") | B12: =IFERROR(IF('入力シート'!$A12="","",'入力シート'!B12),"") | C12: =IFERROR(IF('入力シート'!$A12="","",'入力シート'!C12),"") | D12: =IFERROR(IF('入力シート'!$A12="","",'入力シート'!D12),"") | E12: =IFERROR(IF('入力シート'!$A12="","",'入力シート'!I12),"") | F12: =IFERROR(IF('入力シート'!$A12="","",'入力シート'!N12),"") | G12: =IFERROR(IF('入力シート'!$A12="","",'入力シート'!O12),"") | H12: =IFERROR(IF('入力シート'!$A12="","",'入力シート'!P12),"") | I12: =IFERROR(IF('入力シート'!$A12="","",'入力シート'!Q12),"") | J12: =IFERROR(IF('入力シート'!$A12="","",'入力シート'!R12),"") | K12: =IFERROR(IF('入力シート'!$A12="","",IF(H12>='設定'!$B$4,"OK",IF(H12>='設定'!$B$5,"注意","要改善"))),"")
A13: =IFERROR(IF('入力シート'!$A13="","",'入力シート'!A13),"") | B13: =IFERROR(IF('入力シート'!$A13="","",'入力シート'!B13),"") | C13: =IFERROR(IF('入力シート'!$A13="","",'入力シート'!C13),"") | D13: =IFERROR(IF('入力シート'!$A13="","",'入力シート'!D13),"") | E13: =IFERROR(IF('入力シート'!$A13="","",'入力シート'!I13),"") | F13: =IFERROR(IF('入力シート'!$A13="","",'入力シート'!N13),"") | G13: =IFERROR(IF('入力シート'!$A13="","",'入力シート'!O13),"") | H13: =IFERROR(IF('入力シート'!$A13="","",'入力シート'!P13),"") | I13: =IFERROR(IF('入力シート'!$A13="","",'入力シート'!Q13),"") | J13: =IFERROR(IF('入力シート'!$A13="","",'入力シート'!R13),"") | K13: =IFERROR(IF('入力シート'!$A13="","",IF(H13>='設定'!$B$4,"OK",IF(H13>='設定'!$B$5,"注意","要改善"))),"")
... A301: =IFERROR(IF('入力シート'!$A301="","",'入力シート'!A301),"") | B301: =IFERROR(IF('入力シート'!$A301="","",'入力シート'!B301),"") | C301: =IFERROR(IF('入力シート'!$A301="","",'入力シート'!C301),"") | D301: =IFERROR(IF('入力シート'!$A301="","",'入力シート'!D301),"") | E301: =IFERROR(IF('入力シート'!$A301="","",'入力シート'!I301),"") | F301: =IFERROR(IF('入力シート'!$A301="","",'入力シート'!N301),"") | G301: =IFERROR(IF('入力シート'!$A301="","",'入力シート'!O301),"") | H301: =IFERROR(IF('入力シート'!$A301="","",'入力シート'!P301),"") | I301: =IFERROR(IF('入力シート'!$A301="","",'入力シート'!Q301),"") | J301: =IFERROR(IF('入力シート'!$A301="","",'入力シート'!R301),"") | K301: =IFERROR(IF('入力シート'!$A301="","",IF(H301>='設定'!$B$4,"OK",IF(H301>='設定'!$B$5,"注意","要改善"))),"")

Sheet 粗利分析
A1: 粗利分析ダッシュボード
A3: 項目 | B3: 金額・率 | C3: コメント
A4: お客様見積合計（税抜） | B4: ='社内実行予算書'!B18
A5: 社内実行予算合計 | B5: ='社内実行予算書'!C18
A6: 粗利額 | B6: ='社内実行予算書'!D18
A7: 粗利率 | B7: =IFERROR(B6/B4,0)
A8: 税込見積合計 | B8: ='お客様見積書'!D22
A9: 目標粗利率 | B9: ='設定'!$B$4
A11: 工区・部屋 | B11: お客様見積 | C11: 社内実行予算 | D11: 粗利額 | E11: 粗利率 | F11: 判定 | G11: 比率バー | H11: 備考
A12: ='社内実行予算書'!A4 | B12: ='社内実行予算書'!B4 | C12: ='社内実行予算書'!C4 | D12: ='社内実行予算書'!D4 | E12: ='社内実行予算書'!E4 | F12: ='社内実行予算書'!G4 | G12: ='社内実行予算書'!E4
A13: ='社内実行予算書'!A5 | B13: ='社内実行予算書'!B5 | C13: ='社内実行予算書'!C5 | D13: ='社内実行予算書'!D5 | E13: ='社内実行予算書'!E5 | F13: ='社内実行予算書'!G5 | G13: ='社内実行予算書'!E5
A14: ='社内実行予算書'!A6 | B14: ='社内実行予算書'!B6 | C14: ='社内実行予算書'!C6 | D14: ='社内実行予算書'!D6 | E14: ='社内実行予算書'!E6 | F14: ='社内実行予算書'!G6 | G14: ='社内実行予算書'!E6
A15: ='社内実行予算書'!A7 | B15: ='社内実行予算書'!B7 | C15: ='社内実行予算書'!C7 | D15: ='社内実行予算書'!D7 | E15: ='社内実行予算書'!E7 | F15: ='社内実行予算書'!G7 | G15: ='社内実行予算書'!E7
A16: ='社内実行予算書'!A8 | B16: ='社内実行予算書'!B8 | C16: ='社内実行予算書'!C8 | D16: ='社内実行予算書'!D8 | E16: ='社内実行予算書'!E8 | F16: ='社内実行予算書'!G8 | G16: ='社内実行予算書'!E8
A17: ='社内実行予算書'!A9 | B17: ='社内実行予算書'!B9 | C17: ='社内実行予算書'!C9 | D17: ='社内実行予算書'!D9 | E17: ='社内実行予算書'!E9 | F17: ='社内実行予算書'!G9 | G17: ='社内実行予算書'!E9
A18: ='社内実行予算書'!A10 | B18: ='社内実行予算書'!B10 | C18: ='社内実行予算書'!C10 | D18: ='社内実行予算書'!D10 | E18: ='社内実行予算書'!E10 | F18: ='社内実行予算書'!G10 | G18: ='社内実行予算書'!E10
A19: ='社内実行予算書'!A11 | B19: ='社内実行予算書'!B11 | C19: ='社内実行予算書'!C11 | D19: ='社内実行予算書'!D11 | E19: ='社内実行予算書'!E11 | F19: ='社内実行予算書'!G11 | G19: ='社内実行予算書'!E11
A20: ='社内実行予算書'!A12 | B20: ='社内実行予算書'!B12 | C20: ='社内実行予算書'!C12 | D20: ='社内実行予算書'!D12 | E20: ='社内実行予算書'!E12 | F20: ='社内実行予算書'!G12 | G20: ='社内実行予算書'!E12
A21: ='社内実行予算書'!A13 | B21: ='社内実行予算書'!B13 | C21: ='社内実行予算書'!C13 | D21: ='社内実行予算書'!D13 | E21: ='社内実行予算書'!E13 | F21: ='社内実行予算書'!G13 | G21: ='社内実行予算書'!E13
A22: ='社内実行予算書'!A14 | B22: ='社内実行予算書'!B14 | C22: ='社内実行予算書'!C14 | D22: ='社内実行予算書'!D14 | E22: ='社内実行予算書'!E14 | F22: ='社内実行予算書'!G14 | G22: ='社内実行予算書'!E14
A23: ='社内実行予算書'!A15 | B23: ='社内実行予算書'!B15 | C23: ='社内実行予算書'!C15 | D23: ='社内実行予算書'!D15 | E23: ='社内実行予算書'!E15 | F23: ='社内実行予算書'!G15 | G23: ='社内実行予算書'!E15
A24: ='社内実行予算書'!A16 | B24: ='社内実行予算書'!B16 | C24: ='社内実行予算書'!C16 | D24: ='社内実行予算書'!D16 | E24: ='社内実行予算書'!E16 | F24: ='社内実行予算書'!G16 | G24: ='社内実行予算書'!E16
A25: ='社内実行予算書'!A18 | B25: ='社内実行予算書'!B18 | C25: ='社内実行予算書'!C18 | D25: ='社内実行予算書'!D18 | E25: ='社内実行予算書'!E18 | F25: ='社内実行予算書'!G18 | G25: ='社内実行予算書'!E18
A27: カテゴリ別内訳（税抜）
A28: カテゴリ | B28: お客様金額 | C28: 実行予算 | D28: 粗利額 | E28: 粗利率
A29: 材料 | B29: =SUMIFS('入力シート'!$I$2:$I$301,'入力シート'!$C$2:$C$301,"材料",'入力シート'!$S$2:$S$301,"表示") | C29: =SUMIFS('入力シート'!$N$2:$N$301,'入力シート'!$C$2:$C$301,"材料",'入力シート'!$S$2:$S$301,"表示") | D29: =B29-C29 | E29: =IFERROR(D29/B29,0)
A30: 施工 | B30: =SUMIFS('入力シート'!$I$2:$I$301,'入力シート'!$C$2:$C$301,"施工",'入力シート'!$S$2:$S$301,"表示") | C30: =SUMIFS('入力シート'!$N$2:$N$301,'入力シート'!$C$2:$C$301,"施工",'入力シート'!$S$2:$S$301,"表示") | D30: =B30-C30 | E30: =IFERROR(D30/B30,0)
A31: 経費 | B31: =SUMIFS('入力シート'!$I$2:$I$301,'入力シート'!$C$2:$C$301,"経費",'入力シート'!$S$2:$S$301,"表示") | C31: =SUMIFS('入力シート'!$N$2:$N$301,'入力シート'!$C$2:$C$301,"経費",'入力シート'!$S$2:$S$301,"表示") | D31: =B31-C31 | E31: =IFERROR(D31/B31,0)
A32: 合計 | B32: =SUM(B29:B31) | C32: =SUM(C29:C31) | D32: =B32-C32 | E32: =IFERROR(D32/B32,0)
